Workbook

Sheet wages HMRC control
A1: 1234ABC Limited | L1: Data from RTI | X1: Dep extended | Z1: Dep Tax and NIC
A2: 46023 | B2: by department | N2: rows | U2: from tables | V2: check | X2: Dep Additions | Z2: Dep Subs and Loans
N3: Total Default | O3: Total Bristol | P3: Total Bath | Q3: Total Exeter | R3: Total Plymouth | S3: Total | U3: Total | X3: Dep Pension contributions
B4: Wages control | C4: 814 | D4: 814 | G4: =S22 -> 45219.74 | H4: 11
B5: Directors remuneration | C5: 478 | E5: All locations | F5: =N5+N6-N12-N13-N14-N20-N21 -> 1940.4 | H5: 2+3-6-7-8-9-10 | L5: Basic Pay | M5: 2 | N5: =INDEX('Dep extended'!A:U,MATCH(N3,'Dep extended'!A:A,0),MATCH(L5,'Dep extended'!7:7,0)) -> 2051.8 | O5: =INDEX('Dep extended'!A:U,MATCH(O3,'Dep extended'!A:A,0),MATCH(L5,'Dep extended'!7:7,0)) -> 11188.52 | P5: =INDEX('Dep extended'!A:U,MATCH(P3,'Dep extended'!A:A,0),MATCH(L5,'Dep extended'!7:7,0)) -> 6876.24 | Q5: =INDEX('Dep extended'!A:U,MATCH(Q3,'Dep extended'!A:A,0),MATCH(L5,'Dep extended'!7:7,0)) -> 8071.69 | R5: =INDEX('Dep extended'!A:U,MATCH(R3,'Dep extended'!A:A,0),MATCH(L5,'Dep extended'!7:7,0)) -> 9289.04 | S5: =SUM(N5:R5) -> 37477.29 | U5: =INDEX('Dep extended'!A:U,MATCH($U$3,'Dep extended'!A:A,0),MATCH(L5,'Dep extended'!7:7,0)) -> 37477.29 | V5: =U5-S5 -> 0
B6: Salaries | C6: 477 | E6: Bristol | F6: =O5+O6-O12-O13-O14-O20-O21 -> 8714.41 | H6: 2+3-6-7-8-9-10 | L6: Total Hourly Pay | M6: 3 | N6: =INDEX('Dep extended'!A:U,MATCH(N3,'Dep extended'!A:A,0),MATCH(L6,'Dep extended'!7:7,0)) -> 0 | O6: =INDEX('Dep extended'!A:U,MATCH(O3,'Dep extended'!A:A,0),MATCH(L6,'Dep extended'!7:7,0)) -> -409.92 | P6: =INDEX('Dep extended'!A:U,MATCH(P3,'Dep extended'!A:A,0),MATCH(L6,'Dep extended'!7:7,0)) -> 0 | Q6: =INDEX('Dep extended'!A:U,MATCH(Q3,'Dep extended'!A:A,0),MATCH(L6,'Dep extended'!7:7,0)) -> 63.41 | R6: =INDEX('Dep extended'!A:U,MATCH(R3,'Dep extended'!A:A,0),MATCH(L6,'Dep extended'!7:7,0)) -> -447.55 | S6: =SUM(N6:R6) -> -794.06 | U6: =INDEX('Dep extended'!$A:$U,MATCH($U$3,'Dep extended'!A:A,0),MATCH(L6,'Dep extended'!$7:$7,0)) -> -794.06 | V6: =U6-S6 -> 0
B7: Salaries | C7: 477 | E7: Bath | F7: =P5+P6-P12-P13-P14-P20-P21 -> 5910.64
B8: Salaries | C8: 477 | E8: Exeter | F8: =Q5+Q6-Q12-Q13-Q14-Q20-Q21 -> 7037.25
B9: Salaries | C9: 477 | E9: Plymouth | F9: =R5+R6-R12-R13-R14-R20-R21 -> 7604 | L9: Holiday Pay | N9: =INDEX('Dep extended'!A:U,MATCH(N3,'Dep extended'!A:A,0),MATCH(L9,'Dep extended'!7:7,0)) -> 0 | O9: =INDEX('Dep extended'!A:U,MATCH(O3,'Dep extended'!A:A,0),MATCH(L9,'Dep extended'!7:7,0)) -> 0 | P9: =INDEX('Dep extended'!A:U,MATCH(P3,'Dep extended'!A:A,0),MATCH(L9,'Dep extended'!7:7,0)) -> 0 | Q9: =INDEX('Dep extended'!A:U,MATCH(Q3,'Dep extended'!A:A,0),MATCH(L9,'Dep extended'!7:7,0)) -> 0 | R9: =INDEX('Dep extended'!A:U,MATCH(R3,'Dep extended'!A:A,0),MATCH(L9,'Dep extended'!7:7,0)) -> 0 | S9: =SUM(N9:R9) -> 0 | U9: =INDEX('Dep extended'!$A:$U,MATCH($U$3,'Dep extended'!A:A,0),MATCH(L9,'Dep extended'!$7:$7,0)) -> 0 | V9: =U9-S9 -> 0
L10: Sick Pay | N10: =INDEX('Dep extended'!A:U,MATCH(N3,'Dep extended'!A:A,0),MATCH(L10,'Dep extended'!7:7,0)) -> 0 | O10: =INDEX('Dep extended'!A:U,MATCH(O3,'Dep extended'!A:A,0),MATCH(L10,'Dep extended'!7:7,0)) -> 0 | P10: =INDEX('Dep extended'!A:U,MATCH(P3,'Dep extended'!A:A,0),MATCH(L10,'Dep extended'!7:7,0)) -> 0 | Q10: =INDEX('Dep extended'!A:U,MATCH(Q3,'Dep extended'!A:A,0),MATCH(L10,'Dep extended'!7:7,0)) -> 0 | R10: =INDEX('Dep extended'!A:U,MATCH(R3,'Dep extended'!A:A,0),MATCH(L10,'Dep extended'!7:7,0)) -> 47.5 | S10: =SUM(N10:R10) -> 47.5 | U10: =INDEX('Dep extended'!$A:$U,MATCH($U$3,'Dep extended'!A:A,0),MATCH(L10,'Dep extended'!$7:$7,0)) -> 47.5 | V10: =U10-S10 -> 0
L11: Parenting Pay | M11: 12 | N11: =INDEX('Dep Additions'!A:N,MATCH(N3,'Dep Additions'!A:A,0),MATCH(L11,'Dep Additions'!7:7,0)) -> 0 | O11: =INDEX('Dep Additions'!A:N,MATCH(O3,'Dep Additions'!A:A,0),MATCH(L11,'Dep Additions'!7:7,0)) -> 0 | P11: =INDEX('Dep Additions'!A:N,MATCH(P3,'Dep Additions'!A:A,0),MATCH(L11,'Dep Additions'!7:7,0)) -> 0 | Q11: =INDEX('Dep Additions'!A:N,MATCH(Q3,'Dep Additions'!A:A,0),MATCH(L11,'Dep Additions'!7:7,0)) -> 0 | R11: =INDEX('Dep Additions'!A:N,MATCH(R3,'Dep Additions'!A:A,0),MATCH(L11,'Dep Additions'!7:7,0)) -> 0 | V11: =U11-S11 -> 0
A12: Additions | B12: Directors loan acc | C12: 835 | E12: All locations | F12: =N27 -> 13059.6 | H12: 15 | L12: Pension Employee Contribution | M12: 6 | N12: =INDEX('Dep extended'!$A:$U,MATCH($N$3,'Dep extended'!$A:$A,0),MATCH(L12,'Dep extended'!$7:$7,0)) -> 0 | O12: =INDEX('Dep extended'!$A:$U,MATCH($O$3,'Dep extended'!$A:$A,0),MATCH(L12,'Dep extended'!$7:$7,0)) -> 289.51 | P12: =INDEX('Dep extended'!$A:$U,MATCH($P$3,'Dep extended'!$A:$A,0),MATCH(L12,'Dep extended'!$7:$7,0)) -> 191.87 | Q12: =INDEX('Dep extended'!$A:$U,MATCH($Q$3,'Dep extended'!$A:$A,0),MATCH(L12,'Dep extended'!$7:$7,0)) -> 221.44 | R12: =INDEX('Dep extended'!$A:$U,MATCH($R$3,'Dep extended'!$A:$A,0),MATCH(L12,'Dep extended'!$7:$7,0)) -> 251.58 | S12: =SUM(N12:R12) -> 954.4 | U12: =INDEX('Dep extended'!$A:$U,MATCH($U$3,'Dep extended'!A:A,0),MATCH(L12,'Dep extended'!$7:$7,0)) -> 954.4 | V12: =U12-S12 -> 0
A13: Additions | B13: Mileage | C13: 486 | E13: All locations | F13: =N26 -> 0 | H13: 14 | L13: Student Loan Repayment | M13: 7 | N13: =INDEX('Dep extended'!$A:$U,MATCH($N$3,'Dep extended'!$A:$A,0),MATCH(L13,'Dep extended'!$7:$7,0)) -> 0 | O13: =INDEX('Dep extended'!$A:$U,MATCH($O$3,'Dep extended'!$A:$A,0),MATCH(L13,'Dep extended'!$7:$7,0)) -> 0 | P13: =INDEX('Dep extended'!$A:$U,MATCH($P$3,'Dep extended'!$A:$A,0),MATCH(L13,'Dep extended'!$7:$7,0)) -> 0 | Q13: =INDEX('Dep extended'!$A:$U,MATCH($Q$3,'Dep extended'!$A:$A,0),MATCH(L13,'Dep extended'!$7:$7,0)) -> 0 | R13: =INDEX('Dep extended'!$A:$U,MATCH($R$3,'Dep extended'!$A:$A,0),MATCH(L13,'Dep extended'!$7:$7,0)) -> 21 | S13: =SUM(N13:R13) -> 21 | U13: =INDEX('Dep extended'!$A:$U,MATCH($U$3,'Dep extended'!A:A,0),MATCH(L13,'Dep extended'!$7:$7,0)) -> 21 | V13: =U13-S13 -> 0
A14: Additions | B14: Mileage | C14: 486 | E14: Bristol | F14: =O26 -> 354.15 | L14: Postgrad Loan Repayment | M14: 8 | N14: =INDEX('Dep extended'!$A:$U,MATCH($N$3,'Dep extended'!$A:$A,0),MATCH(L14,'Dep extended'!$7:$7,0)) -> 0 | O14: =INDEX('Dep extended'!$A:$U,MATCH($O$3,'Dep extended'!$A:$A,0),MATCH(L14,'Dep extended'!$7:$7,0)) -> 0 | P14: =INDEX('Dep extended'!$A:$U,MATCH($P$3,'Dep extended'!$A:$A,0),MATCH(L14,'Dep extended'!$7:$7,0)) -> 0 | Q14: =INDEX('Dep extended'!$A:$U,MATCH($Q$3,'Dep extended'!$A:$A,0),MATCH(L14,'Dep extended'!$7:$7,0)) -> 0 | R14: =INDEX('Dep extended'!$A:$U,MATCH($R$3,'Dep extended'!$A:$A,0),MATCH(L14,'Dep extended'!$7:$7,0)) -> 0 | S14: =SUM(N14:R14) -> 0 | U14: =INDEX('Dep extended'!$A:$U,MATCH($U$3,'Dep extended'!A:A,0),MATCH(L14,'Dep extended'!$7:$7,0)) -> 0 | V14: =U14-S14 -> 0
A15: Additions | B15: Mileage | C15: 486 | E15: Bath | F15: =P26 -> 0
A16: Additions | B16: Mileage | C16: 486 | E16: Exeter | F16: =Q26 -> 23.67 | L16: Payroll Giving | N16: =INDEX('Dep extended'!$A:$U,MATCH($N$3,'Dep extended'!$A:$A,0),MATCH(L16,'Dep extended'!$7:$7,0)) -> 0 | O16: =INDEX('Dep extended'!$A:$U,MATCH($O$3,'Dep extended'!$A:$A,0),MATCH(L16,'Dep extended'!$7:$7,0)) -> 0 | P16: =INDEX('Dep extended'!$A:$U,MATCH($P$3,'Dep extended'!$A:$A,0),MATCH(L16,'Dep extended'!$7:$7,0)) -> 0 | Q16: =INDEX('Dep extended'!$A:$U,MATCH($Q$3,'Dep extended'!$A:$A,0),MATCH(L16,'Dep extended'!$7:$7,0)) -> 0 | R16: =INDEX('Dep extended'!$A:$U,MATCH($R$3,'Dep extended'!$A:$A,0),MATCH(L16,'Dep extended'!$7:$7,0)) -> 0 | S16: =SUM(N16:R16) -> 0 | U16: =INDEX('Dep extended'!$A:$U,MATCH($U$3,'Dep extended'!A:A,0),MATCH(L16,'Dep extended'!$7:$7,0)) -> 0 | V16: =U16-S16 -> 0
A17: Additions | B17: Mileage | C17: 486 | E17: Plymouth | F17: =R26 -> 319.32 | L17: Childcare from employee | N17: =INDEX('Dep extended'!$A:$U,MATCH($N$3,'Dep extended'!$A:$A,0),MATCH(L17,'Dep extended'!$7:$7,0)) -> 0 | O17: =INDEX('Dep extended'!$A:$U,MATCH($O$3,'Dep extended'!$A:$A,0),MATCH(L17,'Dep extended'!$7:$7,0)) -> 0 | P17: =INDEX('Dep extended'!$A:$U,MATCH($P$3,'Dep extended'!$A:$A,0),MATCH(L17,'Dep extended'!$7:$7,0)) -> 0 | Q17: =INDEX('Dep extended'!$A:$U,MATCH($Q$3,'Dep extended'!$A:$A,0),MATCH(L17,'Dep extended'!$7:$7,0)) -> 0 | R17: =INDEX('Dep extended'!$A:$U,MATCH($R$3,'Dep extended'!$A:$A,0),MATCH(L17,'Dep extended'!$7:$7,0)) -> 0 | S17: =SUM(N17:R17) -> 0 | U17: =INDEX('Dep extended'!$A:$U,MATCH($U$3,'Dep extended'!A:A,0),MATCH(L17,'Dep extended'!$7:$7,0)) -> 0 | V17: =U17-S17 -> 0
A18: Additions | B18: Expenses | C18: 487 | E18: All locations | F18: =N25 -> 0 | H18: 13 | L18: Total Deductions | N18: =INDEX('Dep extended'!$A:$U,MATCH($N$3,'Dep extended'!$A:$A,0),MATCH(L18,'Dep extended'!$7:$7,0)) -> 0 | O18: =INDEX('Dep extended'!$A:$U,MATCH($O$3,'Dep extended'!$A:$A,0),MATCH(L18,'Dep extended'!$7:$7,0)) -> 0 | P18: =INDEX('Dep extended'!$A:$U,MATCH($P$3,'Dep extended'!$A:$A,0),MATCH(L18,'Dep extended'!$7:$7,0)) -> 0 | Q18: =INDEX('Dep extended'!$A:$U,MATCH($Q$3,'Dep extended'!$A:$A,0),MATCH(L18,'Dep extended'!$7:$7,0)) -> 0 | R18: =INDEX('Dep extended'!$A:$U,MATCH($R$3,'Dep extended'!$A:$A,0),MATCH(L18,'Dep extended'!$7:$7,0)) -> 0 | S18: =SUM(N18:R18) -> 0 | U18: =INDEX('Dep extended'!$A:$U,MATCH($U$3,'Dep extended'!A:A,0),MATCH(L18,'Dep extended'!$7:$7,0)) -> 0 | V18: =U18-S18 -> 0
A19: Additions | B19: Expenses | C19: 487 | E19: Bristol | F19: =O25 -> 216.8 | L19: Over- Payment | N19: =INDEX('Dep extended'!$A:$U,MATCH($N$3,'Dep extended'!$A:$A,0),MATCH(L19,'Dep extended'!$7:$7,0)) -> 0 | O19: =INDEX('Dep extended'!$A:$U,MATCH($O$3,'Dep extended'!$A:$A,0),MATCH(L19,'Dep extended'!$7:$7,0)) -> 0 | P19: =INDEX('Dep extended'!$A:$U,MATCH($P$3,'Dep extended'!$A:$A,0),MATCH(L19,'Dep extended'!$7:$7,0)) -> 0 | Q19: =INDEX('Dep extended'!$A:$U,MATCH($Q$3,'Dep extended'!$A:$A,0),MATCH(L19,'Dep extended'!$7:$7,0)) -> 0 | R19: =INDEX('Dep extended'!$A:$U,MATCH($R$3,'Dep extended'!$A:$A,0),MATCH(L19,'Dep extended'!$7:$7,0)) -> 0 | S19: =SUM(N19:R19) -> 0 | U19: =INDEX('Dep extended'!$A:$U,MATCH($U$3,'Dep extended'!A:A,0),MATCH(L19,'Dep extended'!$7:$7,0)) -> 0 | V19: =U19-S19 -> 0
A20: Additions | B20: Expenses | C20: 487 | E20: Bath | F20: =P25 -> 0 | L20: Employee NIC | M20: 9 | N20: =INDEX('Dep extended'!A:U,MATCH(N3,'Dep extended'!A:A,0),MATCH(L20,'Dep extended'!7:7,0)) -> 0 | O20: =INDEX('Dep extended'!A:U,MATCH(O3,'Dep extended'!A:A,0),MATCH(L20,'Dep extended'!7:7,0)) -> 386.48 | P20: =INDEX('Dep extended'!A:U,MATCH(P3,'Dep extended'!A:A,0),MATCH(L20,'Dep extended'!7:7,0)) -> 214.73 | Q20: =INDEX('Dep extended'!A:U,MATCH(Q3,'Dep extended'!A:A,0),MATCH(L20,'Dep extended'!7:7,0)) -> 231.61 | R20: =INDEX('Dep extended'!A:U,MATCH(R3,'Dep extended'!A:A,0),MATCH(L20,'Dep extended'!7:7,0)) -> 291.91 | S20: =SUM(N20:R20) -> 1124.73 | U20: =INDEX('Dep extended'!$A:$U,MATCH($U$3,'Dep extended'!A:A,0),MATCH(L20,'Dep extended'!$7:$7,0)) -> 1124.73 | V20: =U20-S20 -> 0
A21: Additions | B21: Expenses | C21: 487 | E21: Exeter | F21: =Q25 -> 10.8 | L21: Tax Deducted | M21: 10 | N21: =INDEX('Dep extended'!A:U,MATCH(N3,'Dep extended'!A:A,0),MATCH(L21,'Dep extended'!7:7,0)) -> 111.4 | O21: =INDEX('Dep extended'!A:U,MATCH(O3,'Dep extended'!A:A,0),MATCH(L21,'Dep extended'!7:7,0)) -> 1388.2 | P21: =INDEX('Dep extended'!A:U,MATCH(P3,'Dep extended'!A:A,0),MATCH(L21,'Dep extended'!7:7,0)) -> 559 | Q21: =INDEX('Dep extended'!A:U,MATCH(Q3,'Dep extended'!A:A,0),MATCH(L21,'Dep extended'!7:7,0)) -> 644.8 | R21: =INDEX('Dep extended'!A:U,MATCH(R3,'Dep extended'!A:A,0),MATCH(L21,'Dep extended'!7:7,0)) -> 673 | S21: =SUM(N21:R21) -> 3376.4 | U21: =INDEX('Dep extended'!$A:$U,MATCH($U$3,'Dep extended'!A:A,0),MATCH(L21,'Dep extended'!$7:$7,0)) -> 3376.4 | V21: =U21-S21 -> 0
A22: Additions | B22: Expenses | C22: 487 | E22: Plymouth | F22: =R25 -> 31.2 | L22: Net Pay | M22: 11 | S22: =INDEX('Dep extended'!A:U,MATCH(S3,'Dep extended'!A:A,0),MATCH(L22,'Dep extended'!7:7,0)) -> 45219.74 | U22: =INDEX('Dep extended'!$A:$U,MATCH($U$3,'Dep extended'!A:A,0),MATCH(L22,'Dep extended'!$7:$7,0)) -> 45219.74 | V22: =U22-S22 -> 0
B23: Salaries | C23: 477 | D23: Backpay/owed | E23: All locations | F23: =N28 -> 0 | L23: Rounding Addition
B24: Salaries | C24: 477 | D24: Backpay/owed | E24: Bristol | F24: =O28 -> 0 | L24: User-Defined Addition
B25: Salaries | C25: 477 | D25: Backpay/owed | E25: Bath | F25: =P28 -> 0 | L25: Expenses | M25: 13 | N25: =INDEX('Dep Additions'!A:N,MATCH(N3,'Dep Additions'!A:A,0),MATCH(L25,'Dep Additions'!7:7,0)) -> 0 | O25: =INDEX('Dep Additions'!A:N,MATCH(O3,'Dep Additions'!A:A,0),MATCH(L25,'Dep Additions'!7:7,0)) -> 216.8 | P25: =INDEX('Dep Additions'!A:N,MATCH(P3,'Dep Additions'!A:A,0),MATCH(L25,'Dep Additions'!7:7,0)) -> 0 | Q25: =INDEX('Dep Additions'!A:N,MATCH(Q3,'Dep Additions'!A:A,0),MATCH(L25,'Dep Additions'!7:7,0)) -> 10.8 | R25: =INDEX('Dep Additions'!A:N,MATCH(R3,'Dep Additions'!A:A,0),MATCH(L25,'Dep Additions'!7:7,0)) -> 31.2 | S25: =SUM(N25:R25) -> 258.8 | U25: =INDEX('Dep Additions'!$A:$N,MATCH($U$3,'Dep Additions'!$A:$A,0),MATCH(L25,'Dep Additions'!$7:$7,0)) -> 258.8 | V25: =U25-S25 -> 0
B26: Salaries | C26: 477 | D26: Backpay/owed | E26: Exeter | F26: =Q28 -> 0 | L26: Mileage | M26: 14 | N26: =INDEX('Dep Additions'!A:N,MATCH(N3,'Dep Additions'!A:A,0),MATCH(L26,'Dep Additions'!7:7,0)) -> 0 | O26: =INDEX('Dep Additions'!A:N,MATCH(O3,'Dep Additions'!A:A,0),MATCH(L26,'Dep Additions'!7:7,0)) -> 354.15 | P26: =INDEX('Dep Additions'!A:N,MATCH(P3,'Dep Additions'!A:A,0),MATCH(L26,'Dep Additions'!7:7,0)) -> 0 | Q26: =INDEX('Dep Additions'!A:N,MATCH(Q3,'Dep Additions'!A:A,0),MATCH(L26,'Dep Additions'!7:7,0)) -> 23.67 | R26: =INDEX('Dep Additions'!A:N,MATCH(R3,'Dep Additions'!A:A,0),MATCH(L26,'Dep Additions'!7:7,0)) -> 319.32 | S26: =SUM(N26:R26) -> 697.14 | U26: =INDEX('Dep Additions'!$A:$N,MATCH($U$3,'Dep Additions'!$A:$A,0),MATCH(L26,'Dep Additions'!$7:$7,0)) -> 697.14 | V26: =U26-S26 -> 0
B27: Salaries | C27: 477 | D27: Backpay/owed | E27: Plymouth | F27: =R28 -> 0 | L27: Director Loan Drawdown | M27: 15 | N27: =INDEX('Dep Additions'!A:N,MATCH(N3,'Dep Additions'!A:A,0),MATCH(L27,'Dep Additions'!7:7,0)) -> 13059.6 | S27: =SUM(N27:R27) -> 13059.6 | U27: =INDEX('Dep Additions'!$A:$N,MATCH($U$3,'Dep Additions'!$A:$A,0),MATCH(L27,'Dep Additions'!$7:$7,0)) -> 13059.6 | V27: =U27-S27 -> 0
A28: Additions | B28: Salaries | C28: 477 | D28: Parenting Pay | E28: All locations | F28: =N11 -> 0 | H28: 12 | L28: Backpay/owed | N28: =INDEX('Dep Additions'!A:N,MATCH(N3,'Dep Additions'!A:A,0),MATCH(L28,'Dep Additions'!7:7,0)) -> 0 | O28: =INDEX('Dep Additions'!A:N,MATCH(O3,'Dep Additions'!A:A,0),MATCH(L28,'Dep Additions'!7:7,0)) -> 0 | P28: =INDEX('Dep Additions'!A:N,MATCH(P3,'Dep Additions'!A:A,0),MATCH(L28,'Dep Additions'!7:7,0)) -> 0 | Q28: =INDEX('Dep Additions'!A:N,MATCH(Q3,'Dep Additions'!A:A,0),MATCH(L28,'Dep Additions'!7:7,0)) -> 0 | R28: =INDEX('Dep Additions'!A:N,MATCH(R3,'Dep Additions'!A:A,0),MATCH(L28,'Dep Additions'!7:7,0)) -> 0 | S28: =SUM(N28:R28) -> 0 | U28: =INDEX('Dep Additions'!$A:$N,MATCH($U$3,'Dep Additions'!$A:$A,0),MATCH(L28,'Dep Additions'!$7:$7,0)) -> 0 | V28: =U28-S28 -> 0
A29: Additions | B29: Salaries | C29: 477 | D29: Parenting Pay | E29: Bristol | F29: =O11 -> 0 | L29: Bonus | U29: =INDEX('Dep Additions'!$A:$N,MATCH($U$3,'Dep Additions'!$A:$A,0),MATCH(L29,'Dep Additions'!$7:$7,0)) -> 0 | V29: =U29-S29 -> 0
A30: Additions | B30: Salaries | C30: 477 | D30: Parenting Pay | E30: Bath | F30: =P11 -> 0
A31: Additions | B31: Salaries | C31: 477 | D31: Parenting Pay | E31: Exeter | F31: =Q11 -> 0
A32: Additions | B32: Salaries | C32: 477 | D32: Parenting Pay | E32: Plymouth | F32: =R11 -> 0 | L32: Pension Total Contribution | M32: 18 | S32: =INDEX('Dep Pension contributions'!A:N,MATCH(S3,'Dep Pension contributions'!A:A,0),MATCH(L32,'Dep Pension contributions'!7:7,0)) -> 1670.24 | U32: =INDEX('Dep Pension contributions'!$A:$N,MATCH($U$3,'Dep Pension contributions'!$A:$A,0),MATCH(L32,'Dep Pension contributions'!$7:$7,0)) -> 1670.24 | V32: =U32-S32 -> 0
B33: Salaries | C33: 477 | D33: Sick pay | E33: All locations | F33: =N10 -> 0 | L33: Total Employee Pension | M33: 16 | N33: =INDEX('Dep Pension contributions'!A:N,MATCH(N3,'Dep Pension contributions'!A:A,0),MATCH(L33,'Dep Pension contributions'!7:7,0)) -> 0 | O33: =INDEX('Dep Pension contributions'!A:N,MATCH(O3,'Dep Pension contributions'!A:A,0),MATCH(L33,'Dep Pension contributions'!7:7,0)) -> 289.51 | P33: =INDEX('Dep Pension contributions'!A:N,MATCH(P3,'Dep Pension contributions'!A:A,0),MATCH(L33,'Dep Pension contributions'!7:7,0)) -> 191.87 | Q33: =INDEX('Dep Pension contributions'!A:N,MATCH(Q3,'Dep Pension contributions'!A:A,0),MATCH(L33,'Dep Pension contributions'!7:7,0)) -> 221.44 | R33: =INDEX('Dep Pension contributions'!A:N,MATCH(R3,'Dep Pension contributions'!A:A,0),MATCH(L33,'Dep Pension contributions'!7:7,0)) -> 251.58 | S33: =SUM(N33:R33) -> 954.4 | U33: =INDEX('Dep Pension contributions'!$A:$N,MATCH($U$3,'Dep Pension contributions'!$A:$A,0),MATCH(L33,'Dep Pension contributions'!$7:$7,0)) -> 954.4 | V33: =U33-S33 -> 0
B34: Salaries | C34: 477 | D34: Sick pay | E34: Bristol | F34: =O10 -> 0 | L34: Total Employer Pension | M34: 17 | N34: =INDEX('Dep Pension contributions'!A:N,MATCH(N3,'Dep Pension contributions'!A:A,0),MATCH(L34,'Dep Pension contributions'!7:7,0)) -> 0 | O34: =INDEX('Dep Pension contributions'!A:N,MATCH(O3,'Dep Pension contributions'!A:A,0),MATCH(L34,'Dep Pension contributions'!7:7,0)) -> 217.15 | P34: =INDEX('Dep Pension contributions'!A:N,MATCH(P3,'Dep Pension contributions'!A:A,0),MATCH(L34,'Dep Pension contributions'!7:7,0)) -> 143.91 | Q34: =INDEX('Dep Pension contributions'!A:N,MATCH(Q3,'Dep Pension contributions'!A:A,0),MATCH(L34,'Dep Pension contributions'!7:7,0)) -> 166.08 | R34: =INDEX('Dep Pension contributions'!A:N,MATCH(R3,'Dep Pension contributions'!A:A,0),MATCH(L34,'Dep Pension contributions'!7:7,0)) -> 188.7 | S34: =SUM(N34:R34) -> 715.84 | U34: =INDEX('Dep Pension contributions'!$A:$N,MATCH($U$3,'Dep Pension contributions'!$A:$A,0),MATCH(L34,'Dep Pension contributions'!$7:$7,0)) -> 715.84 | V34: =U34-S34 -> 0
B35: Salaries | C35: 477 | D35: Sick pay | E35: Bath | F35: =P10 -> 0
B36: Salaries | C36: 477 | D36: Sick pay | E36: Exeter | F36: =Q10 -> 0
B37: Salaries | C37: 477 | D37: Sick pay | E37: Plymouth | F37: =R10 -> 47.5
B38: Salaries | C38: 477 | D38: Loan repayment (overpayment) | E38: All locations | G38: =N55 -> 0
B39: Salaries | C39: 477 | D39: Loan repayment (overpayment) | E39: Bristol | G39: =O55 -> 0 | L39: Employer NIC | M39: 22 | N39: =INDEX('Dep Tax and NIC'!A:N,MATCH(N3,'Dep Tax and NIC'!A:A,0),MATCH(L39,'Dep Tax and NIC'!7:7,0)) -> 182.66 | O39: =INDEX('Dep Tax and NIC'!A:N,MATCH(O3,'Dep Tax and NIC'!A:A,0),MATCH(L39,'Dep Tax and NIC'!7:7,0)) -> 1241.49 | P39: =INDEX('Dep Tax and NIC'!A:N,MATCH(P3,'Dep Tax and NIC'!A:A,0),MATCH(L39,'Dep Tax and NIC'!7:7,0)) -> 781.24 | Q39: =INDEX('Dep Tax and NIC'!A:N,MATCH(Q3,'Dep Tax and NIC'!A:A,0),MATCH(L39,'Dep Tax and NIC'!7:7,0)) -> 907.51 | R39: =INDEX('Dep Tax and NIC'!A:N,MATCH(R3,'Dep Tax and NIC'!A:A,0),MATCH(L39,'Dep Tax and NIC'!7:7,0)) -> 1020.59 | S39: =SUM(N39:R39) -> 4133.49 | U39: =INDEX('Dep Tax and NIC'!$A:$N,MATCH($U$3,'Dep Tax and NIC'!$A:$A,0),MATCH(L39,'Dep Tax and NIC'!$7:$7,0)) -> 4133.49 | V39: =U39-S39 -> 0
B40: Salaries | C40: 477 | D40: Loan repayment (overpayment) | E40: Bath | G40: =P55 -> 0 | L40: Total Tax & NIC Due | S40: =VLOOKUP(L40,'Dep Tax and NIC'!A:B,2,0) -> 8655.62
...

Sheet Dep extended
A2: 1234ABC Limited 2025-26
A3: RTI Full Payment Submission (FPS)
A4: 46054
A5: Department Summary, Layout: Extended
A7: Department | B7: Tax Code | C7: Total Payments | D7: Basic Pay | E7: Total Hourly Pay | F7: Total Hours | G7: Total Additions | H7: Holiday Pay | I7: Sick Pay | J7: Parenting Pay | K7: Pension Employee Contribution | L7: Student Loan Repayment | M7: Postgrad Loan Repayment | N7: Attachments | O7: Payroll Giving | P7: Childcare from employee | Q7: Total Deductions | R7: Over- Payment | S7: Employee NIC | T7: Tax Deducted | U7: Net Pay
A8: Total Default | C8: 15111.4 | D8: 2051.8 | E8: 0 | F8: 0 | G8: 13059.6 | H8: 0 | I8: 0 | J8: 0 | K8: 0 | L8: 0 | M8: 0 | N8: 0 | O8: 0 | P8: 0 | Q8: 0 | R8: 0 | S8: 0 | T8: 111.4 | U8: 15000
A9: Total Bristol | C9: 11349.55 | D9: 11188.52 | E9: -409.92 | F9: -4 | G9: 570.95 | H9: 0 | I9: 0 | J9: 0 | K9: 289.51 | L9: 0 | M9: 0 | N9: 0 | O9: 0 | P9: 0 | Q9: 0 | R9: 0 | S9: 386.48 | T9: 1388.2 | U9: 9285.36
A10: Total Bath | C10: 6876.24 | D10: 6876.24 | E10: 0 | F10: 0 | G10: 0 | H10: 0 | I10: 0 | J10: 0 | K10: 191.87 | L10: 0 | M10: 0 | N10: 0 | O10: 0 | P10: 0 | Q10: 0 | R10: 0 | S10: 214.73 | T10: 559 | U10: 5910.64
A11: Total Exeter | C11: 8169.57 | D11: 8071.69 | E11: 63.41 | F11: 11 | G11: 34.47 | H11: 0 | I11: 0 | J11: 0 | K11: 221.44 | L11: 0 | M11: 0 | N11: 0 | O11: 0 | P11: 0 | Q11: 0 | R11: 0 | S11: 231.61 | T11: 644.8 | U11: 7021.72
A12: Total Plymouth | C12: 9239.51 | D12: 9289.04 | E12: -447.55 | F12: -5 | G12: 350.52 | H12: 0 | I12: 47.5 | J12: 0 | K12: 251.58 | L12: 21 | M12: 0 | N12: 0 | O12: 0 | P12: 0 | Q12: 0 | R12: 0 | S12: 291.91 | T12: 673 | U12: 8002.02
A13: Total | C13: 50746.27 | D13: 37477.29 | E13: -794.06 | F13: 2 | G13: 14015.54 | H13: 0 | I13: 47.5 | J13: 0 | K13: 954.4 | L13: 21 | M13: 0 | N13: 0 | O13: 0 | P13: 0 | Q13: 0 | R13: 0 | S13: 1124.73 | T13: 3376.4 | U13: 45219.74
A15: Payrolled Car Benefits for:
A16: John Smith: BMW IX I20
A18: Employer Totals:
B19: PAYE Month
A20: Total Net Pay | B20: 45219.74
A22: TAX:
A23: PAYE Tax | B23: 3376.4
A24: Student Loan Repayments | B24: 21
A25: Total Tax Due | B25: 3397.4
A27: NIC:
A28: Employee NIC | B28: 1124.73
A29: Employer NIC | B29: 4133.49
A30: Total NIC Due | B30: 5258.22
A32: Total Tax & NIC Due | B32: 8655.62
A34: HMRC ACCOUNT:
A35: Tax & NIC due for Feb-2026 | B35: 8655.62
A36: Payment for Feb-2026 | B36: 8655.62
A37: Balance carried forward to Mar-2026 | B37: 0
A39: OTHER PAYMENTS:
A40: Employee Pension Contributions | B40: 954.4
A41: Employer Pension Contributions | B41: 715.84
A42: Total Other Payments | B42: 1670.24
A44: TOTAL NET OUTLAY | B44: 55545.6
A46: Loans advanced | B46: 500
A47: NET OUTLAY incl Loans | B47: 56045.6
A49: Amounts shown in the PAYE Month column are the totals for all the pay periods in that PAYE Month.
A51: The figures in this report are based on the data contained in your payroll file NOW. If you have made changes to your data since submitting the RTI return for this period then the figures in this report may be different from those sent to HMRC originally.

Sheet Dep Additions
A2: 1234ABC Limited 2025-26
A3: RTI Full Payment Submission (FPS)
A4: 46054
A5: Department Summary, Layout: Additions
A7: Department | B7: Sick Pay | C7: Parenting Pay | D7: Holiday Pay | E7: Rounding Addition | F7: User-Defined Addition | G7: Expenses | H7: Mileage | I7: Director Loan Drawdown | J7: Backpay/owed | K7: Bonus | L7: Additions
A8: Total Default | B8: 0 | C8: 0 | D8: 0 | F8: 0 | G8: 0 | H8: 0 | I8: 13059.6 | J8: 0 | K8: 0 | L8: 13059.6
A9: Total Bristol | B9: 0 | C9: 0 | D9: 0 | F9: 0 | G9: 216.8 | H9: 354.15 | I9: 0 | J9: 0 | K9: 0 | L9: 570.95
A10: Total Bath | B10: 0 | C10: 0 | D10: 0 | F10: 0 | G10: 0 | H10: 0 | I10: 0 | J10: 0 | K10: 0 | L10: 0
A11: Total Exeter | B11: 0 | C11: 0 | D11: 0 | F11: 0 | G11: 10.8 | H11: 23.67 | I11: 0 | J11: 0 | K11: 0 | L11: 34.47
A12: Total Plymouth | B12: 47.5 | C12: 0 | D12: 0 | F12: 0 | G12: 31.2 | H12: 319.32 | I12: 0 | J12: 0 | K12: 0 | L12: 398.02
A13: Total | B13: 47.5 | C13: 0 | D13: 0 | E13: 0 | F13: 0 | G13: 258.8 | H13: 697.14 | I13: 13059.6 | J13: 0 | K13: 0 | L13: 14063.04
A15: Payrolled Car Benefits for:
A16: John Smith: BMW IX I20
A18: Employer Totals:
B19: PAYE Month
A20: Total Net Pay | B20: 45219.74
A22: TAX:
A23: PAYE Tax | B23: 3376.4
A24: Student Loan Repayments | B24: 21
A25: Total Tax Due | B25: 3397.4
A27: NIC:
A28: Employee NIC | B28: 1124.73
A29: Employer NIC | B29: 4133.49
A30: Total NIC Due | B30: 5258.22
A32: Total Tax & NIC Due | B32: 8655.62
A34: HMRC ACCOUNT:
A35: Tax & NIC due for Feb-2026 | B35: 8655.62
A36: Payment for Feb-2026 | B36: 8655.62
A37: Balance carried forward to Mar-2026 | B37: 0
A39: OTHER PAYMENTS:
A40: Employee Pension Contributions | B40: 954.4
A41: Employer Pension Contributions | B41: 715.84
A42: Total Other Payments | B42: 1670.24
A44: TOTAL NET OUTLAY | B44: 55545.6
A46: Loans advanced | B46: 500
A47: NET OUTLAY incl Loans | B47: 56045.6
A49: Amounts shown in the PAYE Month column are the totals for all the pay periods in that PAYE Month.
A51: The figures in this report are based on the data contained in your payroll file NOW. If you have made changes to your data since submitting the RTI return for this period then the figures in this report may be different from those sent to HMRC originally.
A52: The figures in this report are based on the data contained in your payroll file NOW. If you have made changes to your data since submitting the RTI return for this period then the figures in this report may be different from those sent to HMRC originally.

Sheet Dep Pension contributions
A2: 1234ABC Limited 2025-26
A3: RTI Full Payment Submission (FPS)
A4: 46054
A5: Department Summary, Layout: Pension Contributions
A7: Department | B7: Pension Employee Contribution | C7: Pension Employer Contribution | D7: Pension Total Contribution | E7: Total Employee Pension | F7: Total Employer Pension | G7: Total Pension Contributions
A8: Total Default | B8: 0 | C8: 0 | D8: 0 | E8: 0 | F8: 0 | G8: 0
A9: Total Bristol | B9: 289.51 | C9: 217.15 | D9: 506.66 | E9: 289.51 | F9: 217.15 | G9: 506.66
A10: Total Bath | B10: 191.87 | C10: 143.91 | D10: 335.78 | E10: 191.87 | F10: 143.91 | G10: 335.78
A11: Total Exeter | B11: 221.44 | C11: 166.08 | D11: 387.52 | E11: 221.44 | F11: 166.08 | G11: 387.52
A12: Total Plymouth | B12: 251.58 | C12: 188.7 | D12: 440.28 | E12: 251.58 | F12: 188.7 | G12: 440.28
A13: Total | B13: 954.4 | C13: 715.84 | D13: 1670.24 | E13: 954.4 | F13: 715.84 | G13: 1670.24
A15: Payrolled Car Benefits for:
A16: John Smith: BMW IX I20
A18: Employer Totals:
B19: PAYE Month
A20: Total Net Pay | B20: 45219.74
A22: TAX:
A23: PAYE Tax | B23: 3376.4
A24: Student Loan Repayments | B24: 21
A25: Total Tax Due | B25: 3397.4
A27: NIC:
A28: Employee NIC | B28: 1124.73
A29: Employer NIC | B29: 4133.49
A30: Total NIC Due | B30: 5258.22
A32: Total Tax & NIC Due | B32: 8655.62
A34: HMRC ACCOUNT:
A35: Tax & NIC due for Feb-2026 | B35: 8655.62
A36: Payment for Feb-2026 | B36: 8655.62
A37: Balance carried forward to Mar-2026 | B37: 0
A39: OTHER PAYMENTS:
A40: Employee Pension Contributions | B40: 954.4
A41: Employer Pension Contributions | B41: 715.84
A42: Total Other Payments | B42: 1670.24
A44: TOTAL NET OUTLAY | B44: 55545.6
A46: Loans advanced | B46: 500
A47: NET OUTLAY incl Loans | B47: 56045.6
A49: Amounts shown in the PAYE Month column are the totals for all the pay periods in that PAYE Month.
A51: The figures in this report are based on the data contained in your payroll file NOW. If you have made changes to your data since submitting the RTI return for this period then the figures in this report may be different from those sent to HMRC originally.
A52: The figures in this report are based on the data contained in your payroll file NOW. If you have made changes to your data since submitting the RTI return for this period then the figures in this report may be different from those sent to HMRC originally.

Sheet Dep Tax and NIC
A2: 1234ABC Limited 2025-26
A3: RTI Full Payment Submission (FPS)
A4: 46054
A5: Department Summary, Layout: Tax & NIC
A7: Department | B7: Tax Code | C7: NI Table Letter | D7: Total Payments | E7: Additions | F7: Deductions | G7: Tax Deducted | H7: Employee NIC | I7: Net Pay | J7: Employer NIC
A8: Total Default | D8: 15111.4 | E8: 13059.6 | F8: 0 | G8: 111.4 | H8: 0 | I8: 15000 | J8: 182.66
A9: Total Bristol | D9: 11349.55 | E9: 570.95 | F9: 289.51 | G9: 1388.2 | H9: 386.48 | I9: 9285.36 | J9: 1241.49
A10: Total Bath | D10: 6876.24 | E10: 0 | F10: 191.87 | G10: 559 | H10: 214.73 | I10: 5910.64 | J10: 781.24
A11: Total Exeter | D11: 8169.57 | E11: 34.47 | F11: 271.44 | G11: 644.8 | H11: 231.61 | I11: 7021.72 | J11: 907.51
A12: Total Plymouth | D12: 9239.51 | E12: 398.02 | F12: 272.58 | G12: 673 | H12: 291.91 | I12: 8002.02 | J12: 1020.59
A13: Total | D13: 50746.27 | E13: 14063.04 | F13: 1025.4 | G13: 3376.4 | H13: 1124.73 | I13: 45219.74 | J13: 4133.49
A15: Payrolled Car Benefits for:
A16: John Smith: BMW IX I20
A18: Employer Totals:
B19: PAYE Month
A20: Total Net Pay | B20: 45219.74
A22: TAX:
A23: PAYE Tax | B23: 3376.4
A24: Student Loan Repayments | B24: 21
A25: Total Tax Due | B25: 3397.4
A27: NIC:
A28: Employee NIC | B28: 1124.73
A29: Employer NIC | B29: 4133.49
A30: Total NIC Due | B30: 5258.22
A32: Total Tax & NIC Due | B32: 8655.62
A34: HMRC ACCOUNT:
A35: Tax & NIC due for Feb-2026 | B35: 8655.62
A36: Payment for Feb-2026 | B36: 8655.62
A37: Balance carried forward to Mar-2026 | B37: 0
A39: OTHER PAYMENTS:
A40: Employee Pension Contributions | B40: 954.4
A41: Employer Pension Contributions | B41: 715.84
A42: Total Other Payments | B42: 1670.24
A44: TOTAL NET OUTLAY | B44: 55545.6
A46: Loans advanced | B46: 500
A47: NET OUTLAY incl Loans | B47: 56045.6
A49: Amounts shown in the PAYE Month column are the totals for all the pay periods in that PAYE Month.
A51: The figures in this report are based on the data contained in your payroll file NOW. If you have made changes to your data since submitting the RTI return for this period then the figures in this report may be different from those sent to HMRC originally.

Sheet Dep  Subs and Loans
A2: 1234ABC Limited 2025-26
A3: RTI Full Payment Submission (FPS)
A4: 46054
A5: Department Summary, Layout: Subs & Loans
A7: Department | B7: Loans | C7: Loans Repayment | D7: Loans Balance
A8: Total Default | B8: 0 | C8: 0
A9: Total Bristol | B9: 0 | C9: 0
A10: Total Bath | B10: 0 | C10: 0
A11: Total Exeter | B11: 500 | C11: 50
A12: Total Plymouth | B12: 0 | C12: 0
A13: Total | B13: 500 | C13: 50 | D13: 450
A15: Payrolled Car Benefits for:
A16: John Smith: BMW IX I20
A18: Employer Totals:
B19: PAYE Month
A20: Total Net Pay | B20: 45219.74
A22: TAX:
A23: PAYE Tax | B23: 3376.4
A24: Student Loan Repayments | B24: 21
A25: Total Tax Due | B25: 3397.4
A27: NIC:
A28: Employee NIC | B28: 1124.73
A29: Employer NIC | B29: 4133.49
A30: Total NIC Due | B30: 5258.22
A32: Total Tax & NIC Due | B32: 8655.62
A34: HMRC ACCOUNT:
A35: Tax & NIC due for Feb-2026 | B35: 8655.62
A36: Payment for Feb-2026 | B36: 8655.62
A37: Balance carried forward to Mar-2026 | B37: 0
A39: OTHER PAYMENTS:
A40: Employee Pension Contributions | B40: 954.4
A41: Employer Pension Contributions | B41: 715.84
A42: Total Other Payments | B42: 1670.24
A44: TOTAL NET OUTLAY | B44: 55545.6
A46: Loans advanced | B46: 500
A47: NET OUTLAY incl Loans | B47: 56045.6
A49: Amounts shown in the PAYE Month column are the totals for all the pay periods in that PAYE Month.
A51: The figures in this report are based on the data contained in your payroll file NOW. If you have made changes to your data since submitting the RTI return for this period then the figures in this report may be different from those sent to HMRC originally.
